<?xml version="1.0"?>
<!-- This URDF was automatically created by SolidWorks to URDF Exporter! Originally created by
Stephen Brawner (brawner@gmail.com) 
     Commit Version: 1.6.0-4-g7f85cfe  Build Version: 1.6.7995.38578
     For more information, please see http://wiki.ros.org/sw_urdf_exporter -->
<robot
  xmlns:xacro="http://www.ros.org/wiki/xacro"
  name="agriculture_robot">

  <link name="dummy_link" />

  <joint name="world_to_base_link=" type="fixed">
    <parent link="dummy_link" />
    <child link="base_link" />
  </joint>

  <link name="base_link">
    <inertial>
      <origin
        xyz="0.000953170793338206 -0.00203670125732843 0.168593368096125"
        rpy="0 0 0" />
      <mass
        value="310.25976377299" />
      <inertia
        ixx="29.9081981248055"
        ixy="-0.00129594543184555"
        ixz="0.108476388051515"
        iyy="29.9099493341021"
        iyz="-0.227771058411677"
        izz="49.0807739520924" />
    </inertial>
    <visual>
      <origin
        xyz="0 0 0"
        rpy="0 0 0" />
      <geometry>
        <mesh
          filename="package://agriculture_robot/meshes/base_link.STL" />
      </geometry>
      <material
        name="">
        <color
          rgba="0.901960784313726 0.92156862745098 0.92156862745098 1" />
      </material>
    </visual>
    <collision>
      <origin
        xyz="0 0 0"
        rpy="0 0 0" />
      <geometry>
        <mesh
          filename="package://agriculture_robot/meshes/base_link.STL" />
      </geometry>
    </collision>
  </link>
  <link name="shoulder_pan_link">
    <inertial>
      <origin
        xyz="4.37019309378567E-06 0.0820545660616732 -0.0116148718498792"
        rpy="0 0 0" />
      <mass
        value="3.07353667216991" />
      <inertia
        ixx="0.0114771266254552"
        ixy="-1.00712621246454E-06"
        ixz="2.439837371449E-07"
        iyy="0.0101197406986664"
        iyz="0.000858541665298787"
        izz="0.010716617811193" />
    </inertial>
    <visual>
      <origin
        xyz="0 0 0"
        rpy="0 0 0" />
      <geometry>
        <mesh
          filename="package://agriculture_robot/meshes/shoulder_pan_link.STL" />
      </geometry>
      <material
        name="">
        <color
          rgba="0.6 0.6 0.6 1" />
      </material>
    </visual>
    <collision>
      <origin
        xyz="0 0 0"
        rpy="0 0 0" />
      <geometry>
        <mesh
          filename="package://agriculture_robot/meshes/shoulder_pan_link.STL" />
      </geometry>
    </collision>
  </link>
  <joint
    name="shoulder_pan_joint"
    type="continuous">
    <origin
      xyz="0.00528419852307351 -0.0112018287746117 0.934339582068716"
      rpy="1.55880786742705 -0.005655077203969 -3.14155875526182" />
    <parent
      link="base_link" />
    <child
      link="shoulder_pan_link" />
    <axis
      xyz="0 1 0" />
  </joint>
  <link name="shoulder_lift_link">
    <inertial>
      <origin
        xyz="1.16933946955611E-05 0.251044070838087 -0.0842901331551335"
        rpy="0 0 0" />
      <mass
        value="8.7124476959073" />
      <inertia
        ixx="0.0965258571269439"
        ixy="-3.21349076909668E-06"
        ixz="-6.74404618236147E-06"
        iyy="0.0199171763170117"
        iyz="0.000589174270435517"
        izz="0.0949167945372024" />
    </inertial>
    <visual>
      <origin
        xyz="0 0 0"
        rpy="0 0 0" />
      <geometry>
        <mesh
          filename="package://agriculture_robot/meshes/shoulder_lift_link.STL" />
      </geometry>
      <material
        name="">
        <color
          rgba="0.6 0.6 0.6 1" />
      </material>
    </visual>
    <collision>
      <origin
        xyz="0 0 0"
        rpy="0 0 0" />
      <geometry>
        <mesh
          filename="package://agriculture_robot/meshes/shoulder_lift_link.STL" />
      </geometry>
    </collision>
  </link>
  <joint
    name="shoulder_lift_joint"
    type="continuous">
    <origin
      xyz="0 0.0935783294773769 -0.086046820325919"
      rpy="0 0 -1.57645160719242" />
    <parent
      link="shoulder_pan_link" />
    <child
      link="shoulder_lift_link" />
    <axis
      xyz="0 0 1" />
  </joint>
  <link name="elbow_link">
    <inertial>
      <origin
        xyz="-1.60157378220616E-06 0.256925332824293 0.0346321212762525"
        rpy="0 0 0" />
      <mass
        value="4.65345497822593" />
      <inertia
        ixx="0.0517126806952898"
        ixy="8.92615579126016E-07"
        ixz="4.29343324349291E-07"
        iyy="0.00595526327510539"
        iyz="-0.000130413122823636"
        izz="0.0514235542189657" />
    </inertial>
    <visual>
      <origin
        xyz="0 0 0"
        rpy="0 0 0" />
      <geometry>
        <mesh
          filename="package://agriculture_robot/meshes/elbow_link.STL" />
      </geometry>
      <material
        name="">
        <color
          rgba="0.6 0.6 0.6 1" />
      </material>
    </visual>
    <collision>
      <origin
        xyz="0 0 0"
        rpy="0 0 0" />
      <geometry>
        <mesh
          filename="package://agriculture_robot/meshes/elbow_link.STL" />
      </geometry>
    </collision>
  </link>
  <joint
    name="elbow_joint"
    type="continuous">
    <origin
      xyz="0.00107827947605443 0.612900000000001 -1.29273222843895E-05"
      rpy="0 0.0119882676643175 0" />
    <parent
      link="shoulder_lift_link" />
    <child
      link="elbow_link" />
    <axis
      xyz="0 0 1" />
  </joint>
  <link name="wrist_1_link">
    <inertial>
      <origin
        xyz="2.93983398536035E-06 0.00973732559422373 -0.0702342359729779"
        rpy="0 0 0" />
      <mass
        value="0.728501747245164" />
      <inertia
        ixx="0.0011150413189406"
        ixy="7.55500394224803E-08"
        ixz="-3.46074446105096E-08"
        iyy="0.000883755392536439"
        iyz="9.07969328947864E-05"
        izz="0.00103094367512972" />
    </inertial>
    <visual>
      <origin
        xyz="0 0 0"
        rpy="0 0 0" />
      <geometry>
        <mesh
          filename="package://agriculture_robot/meshes/wrist_1_link.STL" />
      </geometry>
      <material
        name="">
        <color
          rgba="0.6 0.6 0.6 1" />
      </material>
    </visual>
    <collision>
      <origin
        xyz="0 0 0"
        rpy="0 0 0" />
      <geometry>
        <mesh
          filename="package://agriculture_robot/meshes/wrist_1_link.STL" />
      </geometry>
    </collision>
  </link>
  <joint
    name="wrist_1_joint"
    type="continuous">
    <origin
      xyz="0 0.571599999999999 0"
      rpy="0 0 -1.5707963267949" />
    <parent
      link="elbow_link" />
    <child
      link="wrist_1_link" />
    <axis
      xyz="0 0 1" />
  </joint>
  <link name="wrist_2_link">
    <inertial>
      <origin
        xyz="-3.41592482211439E-06 0.108096484310984 -0.00973740152501074"
        rpy="0 0 0" />
      <mass
        value="0.728503579499185" />
      <inertia
        ixx="0.00111505314792338"
        ixy="-3.15150519800801E-08"
        ixz="7.9376823661956E-08"
        iyy="0.00103092830975253"
        iyz="9.07958131149968E-05"
        izz="0.000883753404950502" />
    </inertial>
    <visual>
      <origin
        xyz="0 0 0"
        rpy="0 0 0" />
      <geometry>
        <mesh
          filename="package://agriculture_robot/meshes/wrist_2_link.STL" />
      </geometry>
      <material
        name="">
        <color
          rgba="0.6 0.6 0.6 1" />
      </material>
    </visual>
    <collision>
      <origin
        xyz="0 0 0"
        rpy="0 0 0" />
      <geometry>
        <mesh
          filename="package://agriculture_robot/meshes/wrist_2_link.STL" />
      </geometry>
    </collision>
  </link>
  <joint
    name="wrist_2_joint"
    type="continuous">
    <origin
      xyz="0 0 -0.077837426320686"
      rpy="0 -3.38977859430351E-05 0" />
    <parent
      link="wrist_1_link" />
    <child
      link="wrist_2_link" />
    <axis
      xyz="0 1 0" />
  </joint>
  <link name="wrist_3_link">
    <inertial>
      <origin
        xyz="-1.80806338234696E-08 -0.00094943152172311 -0.0132195267894431"
        rpy="0 0 0" />
      <mass
        value="0.159236553781319" />
      <inertia
        ixx="8.19108670774833E-05"
        ixy="-2.93851703681572E-11"
        ixz="-3.00602794689126E-11"
        iyy="8.7758343925284E-05"
        iyz="-4.72730714495279E-07"
        izz="0.000149632357255088" />
    </inertial>
    <visual>
      <origin
        xyz="0 0 0"
        rpy="0 0 0" />
      <geometry>
        <mesh
          filename="package://agriculture_robot/meshes/wrist_3_link.STL" />
      </geometry>
      <material
        name="">
        <color
          rgba="0.901960784313726 0.92156862745098 0.92156862745098 1" />
      </material>
    </visual>
    <collision>
      <origin
        xyz="0 0 0"
        rpy="0 0 0" />
      <geometry>
        <mesh
          filename="package://agriculture_robot/meshes/wrist_3_link.STL" />
      </geometry>
    </collision>
  </link>
  <joint
    name="wrist_3_joint"
    type="continuous">
    <origin
      xyz="0 0.1157 -0.0615194007436403"
      rpy="0 0 -1.74664209728874" />
    <parent
      link="wrist_2_link" />
    <child
      link="wrist_3_link" />
    <axis
      xyz="0 0 1" />
  </joint>
  <link name="gripper_link">
    <inertial>
      <origin
        xyz="-1.8147875202601E-08 1.4270505677591 -0.238629638011718"
        rpy="0 0 0" />
      <mass
        value="0.159236554932234" />
      <inertia
        ixx="8.19108710165267E-05"
        ixy="-2.89486501312214E-11"
        ixz="-3.01543968163048E-11"
        iyy="8.77583438479366E-05"
        iyz="-4.72731114706349E-07"
        izz="0.000149632361112369" />
    </inertial>
    <visual>
      <origin
        xyz="0 0 0"
        rpy="0 0 0" />
      <geometry>
        <mesh
          filename="package://agriculture_robot/meshes/gripper_link.STL" />
      </geometry>
      <material
        name="">
        <color
          rgba="0.901960784313726 0.92156862745098 0.92156862745098 1" />
      </material>
    </visual>
    <collision>
      <origin
        xyz="0 0 0"
        rpy="0 0 0" />
      <geometry>
        <mesh
          filename="package://agriculture_robot/meshes/gripper_link.STL" />
      </geometry>
    </collision>
  </link>
  <joint
    name="gripper_joint"
    type="fixed">
    <origin
      xyz="1.37545783040745 0.383796504375487 -0.286771309793904"
      rpy="3.14159265358979 0 -1.29868564046961" />
    <parent
      link="wrist_3_link" />
    <child
      link="gripper_link" />
    <axis
      xyz="0 0 0" />
  </joint>

  <link name="camera_link"> </link>

  <joint name="camera_joint" type="fixed">
    <origin xyz="0.05 0 0" rpy="0 0 0" />
    <parent link="gripper_link" />
    <child link="camera_link" />
  </joint>

  <ros2_control name="GazeboSystem" type="system">
    <hardware>
      <plugin>gazebo_ros2_control/GazeboSystem</plugin>
    </hardware>

    <joint name="shoulder_pan_joint">
      <command_interface name="position">
        <param name="min">-6.2832</param>
        <param name="max">6.2832</param>
      </command_interface>
      <state_interface name="position" />
      <state_interface name="velocity" />
      <state_interface name="effort" />
    </joint>

    <joint name="shoulder_lift_joint">
      <command_interface name="position">
        <param name="min">-6.2832</param>
        <param name="max">6.2832</param>
      </command_interface>
      <state_interface name="position" />
      <state_interface name="velocity" />
      <state_interface name="effort" />
    </joint>

    <joint name="elbow_joint">
      <command_interface name="position">
        <param name="min">-2.7925</param>
        <param name="max">2.7925</param>
      </command_interface>
      <state_interface name="position" />
      <state_interface name="velocity" />
      <state_interface name="effort" />
    </joint>

    <joint name="wrist_1_joint">
      <command_interface name="position">
        <param name="min">-6.2832</param>
        <param name="max">6.2832</param>
      </command_interface>
      <state_interface name="position" />
      <state_interface name="velocity" />
      <state_interface name="effort" />
    </joint>


    <joint name="wrist_2_joint">
      <command_interface name="position">
        <param name="min">-6.2832</param>
        <param name="max">6.2832</param>
      </command_interface>
      <state_interface name="position" />
      <state_interface name="velocity" />
      <state_interface name="effort" />
    </joint>

    <joint name="wrist_3_joint">
      <command_interface name="position">
        <param name="min">-6.2832</param>
        <param name="max">6.2832</param>
      </command_interface>
      <state_interface name="position" />
      <state_interface name="velocity" />
      <state_interface name="effort" />
    </joint>

    <joint name="shoulder_pan_joint">
      <command_interface name="velocity">
        <param name="min">-1000.0</param>
        <param name="max">1000.0</param>
      </command_interface>
      <state_interface name="position" />
      <state_interface name="velocity" />
    </joint>

    <joint name="shoulder_lift_joint">
      <command_interface name="velocity">
        <param name="min">-1000.0</param>
        <param name="max">1000.0</param>
      </command_interface>
      <state_interface name="position" />
      <state_interface name="velocity" />
    </joint>

    <joint name="elbow_joint">
      <command_interface name="velocity">
        <param name="min">-1000.0</param>
        <param name="max">1000.0</param>
      </command_interface>
      <state_interface name="position" />
      <state_interface name="velocity" />
    </joint>

    <joint name="wrist_1_joint">
      <command_interface name="velocity">
        <param name="min">-1000.0</param>
        <param name="max">1000.0</param>
      </command_interface>
      <state_interface name="position" />
      <state_interface name="velocity" />
    </joint>


    <joint name="wrist_2_joint">
      <command_interface name="velocity">
        <param name="min">-1000.0</param>
        <param name="max">1000.0</param>
      </command_interface>
      <state_interface name="position" />
      <state_interface name="velocity" />
    </joint>

    <joint name="wrist_3_joint">
      <command_interface name="velocity">
        <param name="min">-1000.0</param>
        <param name="max">1000.0</param>
      </command_interface>
      <state_interface name="position" />
      <state_interface name="velocity" />
    </joint>


  </ros2_control>

  <gazebo>
    <plugin name="gazebo_ros2_control" filename="libgazebo_ros2_control.so">
      <!--<robot_sim_type>gazebo_ros2_control/DefaultRobotHWSim</robot_sim_type> -->
      <robot_sim_type>gazebo_ros2_control/GazeboSystem</robot_sim_type>
      <!-- <parameters>$(find agriculture_robot)/config/simple_controller.yaml</parameters> -->
      <parameters>$(find agriculture_robot)/config/control.yaml</parameters>
    </plugin>
  </gazebo>

  <gazebo>
    <plugin name='vacuum_gripper' filename='libgazebo_ros_vacuum_gripper.so'>
      <!-- This part can be commented out if not required -->
      <ros>
        <!-- Add a namespace -->
        <namespace>/warehouse_gripper</namespace>
        <!-- Remapping service and topic names -->
        <remapping>switch:=custom_switch</remapping>
        <remapping>grasping:=custom_grasping</remapping>
      </ros>
      <!-- Link associated with gripper -->
      <link_name>wrist_3_link</link_name>
      <!-- Max distance to attract entities -->
      <max_distance>0.2</max_distance>
      <!-- List of entities to be not attracted by the gripper -->
      <fixed>ground_plane</fixed>
      <fixed>wall</fixed>
    </plugin>
  </gazebo>

  <gazebo>
    <plugin filename="libodometry_plugin.so" name="odometry_plugin">
      <!-- Name of the link for which the odometry is required -->
      <frame>wrist_3_link</frame>
      <!-- Any arbitray name for the world frame -->
      <world_frame>odom_world_frame</world_frame>
    </plugin>
  </gazebo>

</robot>